<?xml version="1.0"?>
<robot xmlns:xacro="http://ros.org/wiki/xacro">

  <xacro:macro name="wheel" params="prefix wheel_name parent_link joint_origin_xyz joint_origin_rpy joint_axis_xyz">

    <link name="${prefix}__${wheel_name}"/>

    <joint name="${prefix}__${wheel_name}_joint" type="continuous">
      <origin xyz="${joint_origin_xyz}" rpy="${joint_origin_rpy}"/>
      <parent link="${prefix}__${parent_link}"/>
      <child link="${prefix}__${wheel_name}"/>
      <axis xyz="${joint_axis_xyz}"/>
    </joint>

  </xacro:macro>

</robot>